Microsoft Windows [Version 10.0.19041.985]
(c) Microsoft Corporation. All rights reserved.

C:\Users\Mr Dawani\Desktop\python_stack\pythonstack\django\django_orm>cd ..

C:\Users\Mr Dawani\Desktop\python_stack\pythonstack\django>call djangoPy3Env/scripts/activate
(djangoPy3Env) C:\Users\Mr Dawani\Desktop\python_stack\pythonstack\django>cd .

(djangoPy3Env) C:\Users\Mr Dawani\Desktop\python_stack\pythonstack\django>cd django_orm

(djangoPy3Env) C:\Users\Mr Dawani\Desktop\python_stack\pythonstack\django\django_orm>django-admin startproject book_authors

(djangoPy3Env) C:\Users\Mr Dawani\Desktop\python_stack\pythonstack\django\django_orm>cd book_authors

(djangoPy3Env) C:\Users\Mr Dawani\Desktop\python_stack\pythonstack\django\django_orm\book_authors>python manage.py runserver
Watching for file changes with StatReloader
Performing system checks...

System check identified no issues (0 silenced).

You have 17 unapplied migration(s). Your project may not work properly until you apply the migrations for app(s): admin, auth, contenttypes, sessions.
Run 'python manage.py migrate' to apply them.
May 23, 2021 - 22:10:09
Django version 2.2.4, using settings 'book_authors.settings'
Starting development server at http://127.0.0.1:8000/
Quit the server with CTRL-BREAK.

(djangoPy3Env) C:\Users\Mr Dawani\Desktop\python_stack\pythonstack\django\django_orm\book_authors>python manage.py startapp
usage: manage.py startapp [-h] [--template TEMPLATE] [--extension EXTENSIONS]
                          [--name FILES] [--version] [-v {0,1,2,3}]
                          [--settings SETTINGS] [--pythonpath PYTHONPATH]
                          [--traceback] [--no-color] [--force-color]
                          name [directory]
manage.py startapp: error: You must provide an application name.

(djangoPy3Env) C:\Users\Mr Dawani\Desktop\python_stack\pythonstack\django\django_orm\book_authors>python manage.py startapp book_app

(djangoPy3Env) C:\Users\Mr Dawani\Desktop\python_stack\pythonstack\django\django_orm\book_authors>code ,

(djangoPy3Env) C:\Users\Mr Dawani\Desktop\python_stack\pythonstack\django\django_orm\book_authors>code .

(djangoPy3Env) C:\Users\Mr Dawani\Desktop\python_stack\pythonstack\django\django_orm\book_authors>python makemigration
python: can't open file 'makemigration': [Errno 2] No such file or directory

(djangoPy3Env) C:\Users\Mr Dawani\Desktop\python_stack\pythonstack\django\django_orm\book_authors>python manage.py makemigration
Unknown command: 'makemigration'. Did you mean makemigrations?
Type 'manage.py help' for usage.

(djangoPy3Env) C:\Users\Mr Dawani\Desktop\python_stack\pythonstack\django\django_orm\book_authors>python manage.py makemigrations
No changes detected

(djangoPy3Env) C:\Users\Mr Dawani\Desktop\python_stack\pythonstack\django\django_orm\book_authors>python manage.py migrate
Operations to perform:
  Apply all migrations: admin, auth, contenttypes, sessions
Running migrations:
  Applying contenttypes.0001_initial... OK
  Applying auth.0001_initial... OK
  Applying admin.0001_initial... OK
  Applying admin.0002_logentry_remove_auto_add... OK
  Applying admin.0003_logentry_add_action_flag_choices... OK
  Applying contenttypes.0002_remove_content_type_name... OK
  Applying auth.0002_alter_permission_name_max_length... OK
  Applying auth.0003_alter_user_email_max_length... OK
  Applying auth.0004_alter_user_username_opts... OK
  Applying auth.0005_alter_user_last_login_null... OK
  Applying auth.0006_require_contenttypes_0002... OK
  Applying auth.0007_alter_validators_add_error_messages... OK
  Applying auth.0008_alter_user_username_max_length... OK
  Applying auth.0009_alter_user_last_name_max_length... OK
  Applying auth.0010_alter_group_name_max_length... OK
  Applying auth.0011_update_proxy_permissions... OK
  Applying sessions.0001_initial... OK

(djangoPy3Env) C:\Users\Mr Dawani\Desktop\python_stack\pythonstack\django\django_orm\book_authors>python manage.py makemigrations
Traceback (most recent call last):
  File "C:\Users\Mr Dawani\Desktop\python_stack\pythonstack\django\djangoPy3Env\lib\site-packages\django\urls\resolvers.py", line 581, in url_patterns
    iter(patterns)
TypeError: 'module' object is not iterable

During handling of the above exception, another exception occurred:

Traceback (most recent call last):
  File "manage.py", line 21, in <module>
    main()
  File "manage.py", line 17, in main
    execute_from_command_line(sys.argv)
  File "C:\Users\Mr Dawani\Desktop\python_stack\pythonstack\django\djangoPy3Env\lib\site-packages\django\core\management\__init__.py", line 381, in execute_from_command_line
    utility.execute()
  File "C:\Users\Mr Dawani\Desktop\python_stack\pythonstack\django\djangoPy3Env\lib\site-packages\django\core\management\__init__.py", line 375, in execute
    self.fetch_command(subcommand).run_from_argv(self.argv)
  File "C:\Users\Mr Dawani\Desktop\python_stack\pythonstack\django\djangoPy3Env\lib\site-packages\django\core\management\base.py", line 323, in run_from_argv
    self.execute(*args, **cmd_options)
  File "C:\Users\Mr Dawani\Desktop\python_stack\pythonstack\django\djangoPy3Env\lib\site-packages\django\core\management\base.py", line 361, in execute
    self.check()
  File "C:\Users\Mr Dawani\Desktop\python_stack\pythonstack\django\djangoPy3Env\lib\site-packages\django\core\management\base.py", line 390, in check
    include_deployment_checks=include_deployment_checks,
  File "C:\Users\Mr Dawani\Desktop\python_stack\pythonstack\django\djangoPy3Env\lib\site-packages\django\core\management\base.py", line 377, in _run_checks
    return checks.run_checks(**kwargs)
  File "C:\Users\Mr Dawani\Desktop\python_stack\pythonstack\django\djangoPy3Env\lib\site-packages\django\core\checks\registry.py", line 72, in run_checks
    new_errors = check(app_configs=app_configs)
  File "C:\Users\Mr Dawani\Desktop\python_stack\pythonstack\django\djangoPy3Env\lib\site-packages\django\core\checks\urls.py", line 13, in check_url_config
    return check_resolver(resolver)
  File "C:\Users\Mr Dawani\Desktop\python_stack\pythonstack\django\djangoPy3Env\lib\site-packages\django\core\checks\urls.py", line 23, in check_resolver
    return check_method()
  File "C:\Users\Mr Dawani\Desktop\python_stack\pythonstack\django\djangoPy3Env\lib\site-packages\django\urls\resolvers.py", line 399, in check
    messages.extend(check_resolver(pattern))
  File "C:\Users\Mr Dawani\Desktop\python_stack\pythonstack\django\djangoPy3Env\lib\site-packages\django\core\checks\urls.py", line 23, in check_resolver
    return check_method()
  File "C:\Users\Mr Dawani\Desktop\python_stack\pythonstack\django\djangoPy3Env\lib\site-packages\django\urls\resolvers.py", line 398, in check
    for pattern in self.url_patterns:
  File "C:\Users\Mr Dawani\Desktop\python_stack\pythonstack\django\djangoPy3Env\lib\site-packages\django\utils\functional.py", line 80, in __get__
    res = instance.__dict__[self.name] = self.func(instance)
  File "C:\Users\Mr Dawani\Desktop\python_stack\pythonstack\django\djangoPy3Env\lib\site-packages\django\urls\resolvers.py", line 588, in url_patterns
    raise ImproperlyConfigured(msg.format(name=self.urlconf_name))
django.core.exceptions.ImproperlyConfigured: The included URLconf '<module 'book_app.urls' from 'C:\\Users\\Mr Dawani\\Desktop\\python_stack\\pythonstack\\django\\django_orm\\book_authors\\book_app\\urls.py'>' does not appear to have any patterns in it. If you see valid patterns in the file then the issue is probably caused by a circular import.

(djangoPy3Env) C:\Users\Mr Dawani\Desktop\python_stack\pythonstack\django\django_orm\book_authors>python manage.py makemigrations
Traceback (most recent call last):
  File "C:\Users\Mr Dawani\Desktop\python_stack\pythonstack\django\djangoPy3Env\lib\site-packages\django\urls\resolvers.py", line 581, in url_patterns
    iter(patterns)
TypeError: 'module' object is not iterable

During handling of the above exception, another exception occurred:

Traceback (most recent call last):
  File "manage.py", line 21, in <module>
    main()
  File "manage.py", line 17, in main
    execute_from_command_line(sys.argv)
  File "C:\Users\Mr Dawani\Desktop\python_stack\pythonstack\django\djangoPy3Env\lib\site-packages\django\core\management\__init__.py", line 381, in execute_from_command_line
    utility.execute()
  File "C:\Users\Mr Dawani\Desktop\python_stack\pythonstack\django\djangoPy3Env\lib\site-packages\django\core\management\__init__.py", line 375, in execute
    self.fetch_command(subcommand).run_from_argv(self.argv)
  File "C:\Users\Mr Dawani\Desktop\python_stack\pythonstack\django\djangoPy3Env\lib\site-packages\django\core\management\base.py", line 323, in run_from_argv
    self.execute(*args, **cmd_options)
  File "C:\Users\Mr Dawani\Desktop\python_stack\pythonstack\django\djangoPy3Env\lib\site-packages\django\core\management\base.py", line 361, in execute
    self.check()
  File "C:\Users\Mr Dawani\Desktop\python_stack\pythonstack\django\djangoPy3Env\lib\site-packages\django\core\management\base.py", line 390, in check
    include_deployment_checks=include_deployment_checks,
  File "C:\Users\Mr Dawani\Desktop\python_stack\pythonstack\django\djangoPy3Env\lib\site-packages\django\core\management\base.py", line 377, in _run_checks
    return checks.run_checks(**kwargs)
  File "C:\Users\Mr Dawani\Desktop\python_stack\pythonstack\django\djangoPy3Env\lib\site-packages\django\core\checks\registry.py", line 72, in run_checks
    new_errors = check(app_configs=app_configs)
  File "C:\Users\Mr Dawani\Desktop\python_stack\pythonstack\django\djangoPy3Env\lib\site-packages\django\core\checks\urls.py", line 13, in check_url_config
    return check_resolver(resolver)
  File "C:\Users\Mr Dawani\Desktop\python_stack\pythonstack\django\djangoPy3Env\lib\site-packages\django\core\checks\urls.py", line 23, in check_resolver
    return check_method()
  File "C:\Users\Mr Dawani\Desktop\python_stack\pythonstack\django\djangoPy3Env\lib\site-packages\django\urls\resolvers.py", line 399, in check
    messages.extend(check_resolver(pattern))
  File "C:\Users\Mr Dawani\Desktop\python_stack\pythonstack\django\djangoPy3Env\lib\site-packages\django\core\checks\urls.py", line 23, in check_resolver
    return check_method()
  File "C:\Users\Mr Dawani\Desktop\python_stack\pythonstack\django\djangoPy3Env\lib\site-packages\django\urls\resolvers.py", line 398, in check
    for pattern in self.url_patterns:
  File "C:\Users\Mr Dawani\Desktop\python_stack\pythonstack\django\djangoPy3Env\lib\site-packages\django\utils\functional.py", line 80, in __get__
    res = instance.__dict__[self.name] = self.func(instance)
  File "C:\Users\Mr Dawani\Desktop\python_stack\pythonstack\django\djangoPy3Env\lib\site-packages\django\urls\resolvers.py", line 588, in url_patterns
    raise ImproperlyConfigured(msg.format(name=self.urlconf_name))
django.core.exceptions.ImproperlyConfigured: The included URLconf '<module 'book_app.urls' from 'C:\\Users\\Mr Dawani\\Desktop\\python_stack\\pythonstack\\django\\django_orm\\book_authors\\book_app\\urls.py'>' does not appear to have any patterns in it. If you see valid patterns in the file then the issue is probably caused by a circular import.

(djangoPy3Env) C:\Users\Mr Dawani\Desktop\python_stack\pythonstack\django\django_orm\book_authors>python manage.py migrate
Traceback (most recent call last):
  File "C:\Users\Mr Dawani\Desktop\python_stack\pythonstack\django\djangoPy3Env\lib\site-packages\django\urls\resolvers.py", line 581, in url_patterns
    iter(patterns)
TypeError: 'module' object is not iterable

During handling of the above exception, another exception occurred:

Traceback (most recent call last):
  File "manage.py", line 21, in <module>
    main()
  File "manage.py", line 17, in main
    execute_from_command_line(sys.argv)
  File "C:\Users\Mr Dawani\Desktop\python_stack\pythonstack\django\djangoPy3Env\lib\site-packages\django\core\management\__init__.py", line 381, in execute_from_command_line
    utility.execute()
  File "C:\Users\Mr Dawani\Desktop\python_stack\pythonstack\django\djangoPy3Env\lib\site-packages\django\core\management\__init__.py", line 375, in execute
    self.fetch_command(subcommand).run_from_argv(self.argv)
  File "C:\Users\Mr Dawani\Desktop\python_stack\pythonstack\django\djangoPy3Env\lib\site-packages\django\core\management\base.py", line 323, in run_from_argv
    self.execute(*args, **cmd_options)
  File "C:\Users\Mr Dawani\Desktop\python_stack\pythonstack\django\djangoPy3Env\lib\site-packages\django\core\management\base.py", line 361, in execute
    self.check()
  File "C:\Users\Mr Dawani\Desktop\python_stack\pythonstack\django\djangoPy3Env\lib\site-packages\django\core\management\base.py", line 390, in check
    include_deployment_checks=include_deployment_checks,
  File "C:\Users\Mr Dawani\Desktop\python_stack\pythonstack\django\djangoPy3Env\lib\site-packages\django\core\management\commands\migrate.py", line 65, in _run_checks
    issues.extend(super()._run_checks(**kwargs))
  File "C:\Users\Mr Dawani\Desktop\python_stack\pythonstack\django\djangoPy3Env\lib\site-packages\django\core\management\base.py", line 377, in _run_checks
    return checks.run_checks(**kwargs)
  File "C:\Users\Mr Dawani\Desktop\python_stack\pythonstack\django\djangoPy3Env\lib\site-packages\django\core\checks\registry.py", line 72, in run_checks
    new_errors = check(app_configs=app_configs)
  File "C:\Users\Mr Dawani\Desktop\python_stack\pythonstack\django\djangoPy3Env\lib\site-packages\django\core\checks\urls.py", line 13, in check_url_config
    return check_resolver(resolver)
  File "C:\Users\Mr Dawani\Desktop\python_stack\pythonstack\django\djangoPy3Env\lib\site-packages\django\core\checks\urls.py", line 23, in check_resolver
    return check_method()
  File "C:\Users\Mr Dawani\Desktop\python_stack\pythonstack\django\djangoPy3Env\lib\site-packages\django\urls\resolvers.py", line 399, in check
    messages.extend(check_resolver(pattern))
  File "C:\Users\Mr Dawani\Desktop\python_stack\pythonstack\django\djangoPy3Env\lib\site-packages\django\core\checks\urls.py", line 23, in check_resolver
    return check_method()
  File "C:\Users\Mr Dawani\Desktop\python_stack\pythonstack\django\djangoPy3Env\lib\site-packages\django\urls\resolvers.py", line 398, in check
    for pattern in self.url_patterns:
  File "C:\Users\Mr Dawani\Desktop\python_stack\pythonstack\django\djangoPy3Env\lib\site-packages\django\utils\functional.py", line 80, in __get__
    res = instance.__dict__[self.name] = self.func(instance)
  File "C:\Users\Mr Dawani\Desktop\python_stack\pythonstack\django\djangoPy3Env\lib\site-packages\django\urls\resolvers.py", line 588, in url_patterns
    raise ImproperlyConfigured(msg.format(name=self.urlconf_name))
django.core.exceptions.ImproperlyConfigured: The included URLconf '<module 'book_app.urls' from 'C:\\Users\\Mr Dawani\\Desktop\\python_stack\\pythonstack\\django\\django_orm\\book_authors\\book_app\\urls.py'>' does not appear to have any patterns in it. If you see valid patterns in the file then the issue is probably caused by a circular import.

(djangoPy3Env) C:\Users\Mr Dawani\Desktop\python_stack\pythonstack\django\django_orm\book_authors>python manage.py makemigrates
Unknown command: 'makemigrates'. Did you mean makemigrations?
Type 'manage.py help' for usage.

(djangoPy3Env) C:\Users\Mr Dawani\Desktop\python_stack\pythonstack\django\django_orm\book_authors>python manage.py makemigrations
Traceback (most recent call last):
  File "C:\Users\Mr Dawani\Desktop\python_stack\pythonstack\django\djangoPy3Env\lib\site-packages\django\urls\resolvers.py", line 581, in url_patterns
    iter(patterns)
TypeError: 'module' object is not iterable

During handling of the above exception, another exception occurred:

Traceback (most recent call last):
  File "manage.py", line 21, in <module>
    main()
  File "manage.py", line 17, in main
    execute_from_command_line(sys.argv)
  File "C:\Users\Mr Dawani\Desktop\python_stack\pythonstack\django\djangoPy3Env\lib\site-packages\django\core\management\__init__.py", line 381, in execute_from_command_line
    utility.execute()
  File "C:\Users\Mr Dawani\Desktop\python_stack\pythonstack\django\djangoPy3Env\lib\site-packages\django\core\management\__init__.py", line 375, in execute
    self.fetch_command(subcommand).run_from_argv(self.argv)
  File "C:\Users\Mr Dawani\Desktop\python_stack\pythonstack\django\djangoPy3Env\lib\site-packages\django\core\management\base.py", line 323, in run_from_argv
    self.execute(*args, **cmd_options)
  File "C:\Users\Mr Dawani\Desktop\python_stack\pythonstack\django\djangoPy3Env\lib\site-packages\django\core\management\base.py", line 361, in execute
    self.check()
  File "C:\Users\Mr Dawani\Desktop\python_stack\pythonstack\django\djangoPy3Env\lib\site-packages\django\core\management\base.py", line 390, in check
    include_deployment_checks=include_deployment_checks,
  File "C:\Users\Mr Dawani\Desktop\python_stack\pythonstack\django\djangoPy3Env\lib\site-packages\django\core\management\base.py", line 377, in _run_checks
    return checks.run_checks(**kwargs)
  File "C:\Users\Mr Dawani\Desktop\python_stack\pythonstack\django\djangoPy3Env\lib\site-packages\django\core\checks\registry.py", line 72, in run_checks
    new_errors = check(app_configs=app_configs)
  File "C:\Users\Mr Dawani\Desktop\python_stack\pythonstack\django\djangoPy3Env\lib\site-packages\django\core\checks\urls.py", line 13, in check_url_config
    return check_resolver(resolver)
  File "C:\Users\Mr Dawani\Desktop\python_stack\pythonstack\django\djangoPy3Env\lib\site-packages\django\core\checks\urls.py", line 23, in check_resolver
    return check_method()
  File "C:\Users\Mr Dawani\Desktop\python_stack\pythonstack\django\djangoPy3Env\lib\site-packages\django\urls\resolvers.py", line 399, in check
    messages.extend(check_resolver(pattern))
  File "C:\Users\Mr Dawani\Desktop\python_stack\pythonstack\django\djangoPy3Env\lib\site-packages\django\core\checks\urls.py", line 23, in check_resolver
    return check_method()
  File "C:\Users\Mr Dawani\Desktop\python_stack\pythonstack\django\djangoPy3Env\lib\site-packages\django\urls\resolvers.py", line 398, in check
    for pattern in self.url_patterns:
  File "C:\Users\Mr Dawani\Desktop\python_stack\pythonstack\django\djangoPy3Env\lib\site-packages\django\utils\functional.py", line 80, in __get__
    res = instance.__dict__[self.name] = self.func(instance)
  File "C:\Users\Mr Dawani\Desktop\python_stack\pythonstack\django\djangoPy3Env\lib\site-packages\django\urls\resolvers.py", line 588, in url_patterns
    raise ImproperlyConfigured(msg.format(name=self.urlconf_name))
django.core.exceptions.ImproperlyConfigured: The included URLconf '<module 'book_app.urls' from 'C:\\Users\\Mr Dawani\\Desktop\\python_stack\\pythonstack\\django\\django_orm\\book_authors\\book_app\\urls.py'>' does not appear to have any patterns in it. If you see valid patterns in the file then the issue is probably caused by a circular import.

(djangoPy3Env) C:\Users\Mr Dawani\Desktop\python_stack\pythonstack\django\django_orm\book_authors>python manage.py migrate
Traceback (most recent call last):
  File "C:\Users\Mr Dawani\Desktop\python_stack\pythonstack\django\djangoPy3Env\lib\site-packages\django\urls\resolvers.py", line 581, in url_patterns
    iter(patterns)
TypeError: 'module' object is not iterable

During handling of the above exception, another exception occurred:

Traceback (most recent call last):
  File "manage.py", line 21, in <module>
    main()
  File "manage.py", line 17, in main
    execute_from_command_line(sys.argv)
  File "C:\Users\Mr Dawani\Desktop\python_stack\pythonstack\django\djangoPy3Env\lib\site-packages\django\core\management\__init__.py", line 381, in execute_from_command_line
    utility.execute()
  File "C:\Users\Mr Dawani\Desktop\python_stack\pythonstack\django\djangoPy3Env\lib\site-packages\django\core\management\__init__.py", line 375, in execute
    self.fetch_command(subcommand).run_from_argv(self.argv)
  File "C:\Users\Mr Dawani\Desktop\python_stack\pythonstack\django\djangoPy3Env\lib\site-packages\django\core\management\base.py", line 323, in run_from_argv
    self.execute(*args, **cmd_options)
  File "C:\Users\Mr Dawani\Desktop\python_stack\pythonstack\django\djangoPy3Env\lib\site-packages\django\core\management\base.py", line 361, in execute
    self.check()
  File "C:\Users\Mr Dawani\Desktop\python_stack\pythonstack\django\djangoPy3Env\lib\site-packages\django\core\management\base.py", line 390, in check
    include_deployment_checks=include_deployment_checks,
  File "C:\Users\Mr Dawani\Desktop\python_stack\pythonstack\django\djangoPy3Env\lib\site-packages\django\core\management\commands\migrate.py", line 65, in _run_checks
    issues.extend(super()._run_checks(**kwargs))
  File "C:\Users\Mr Dawani\Desktop\python_stack\pythonstack\django\djangoPy3Env\lib\site-packages\django\core\management\base.py", line 377, in _run_checks
    return checks.run_checks(**kwargs)
  File "C:\Users\Mr Dawani\Desktop\python_stack\pythonstack\django\djangoPy3Env\lib\site-packages\django\core\checks\registry.py", line 72, in run_checks
    new_errors = check(app_configs=app_configs)
  File "C:\Users\Mr Dawani\Desktop\python_stack\pythonstack\django\djangoPy3Env\lib\site-packages\django\core\checks\urls.py", line 13, in check_url_config
    return check_resolver(resolver)
  File "C:\Users\Mr Dawani\Desktop\python_stack\pythonstack\django\djangoPy3Env\lib\site-packages\django\core\checks\urls.py", line 23, in check_resolver
    return check_method()
  File "C:\Users\Mr Dawani\Desktop\python_stack\pythonstack\django\djangoPy3Env\lib\site-packages\django\urls\resolvers.py", line 399, in check
    messages.extend(check_resolver(pattern))
  File "C:\Users\Mr Dawani\Desktop\python_stack\pythonstack\django\djangoPy3Env\lib\site-packages\django\core\checks\urls.py", line 23, in check_resolver
    return check_method()
  File "C:\Users\Mr Dawani\Desktop\python_stack\pythonstack\django\djangoPy3Env\lib\site-packages\django\urls\resolvers.py", line 398, in check
    for pattern in self.url_patterns:
  File "C:\Users\Mr Dawani\Desktop\python_stack\pythonstack\django\djangoPy3Env\lib\site-packages\django\utils\functional.py", line 80, in __get__
    res = instance.__dict__[self.name] = self.func(instance)
  File "C:\Users\Mr Dawani\Desktop\python_stack\pythonstack\django\djangoPy3Env\lib\site-packages\django\urls\resolvers.py", line 588, in url_patterns
    raise ImproperlyConfigured(msg.format(name=self.urlconf_name))
django.core.exceptions.ImproperlyConfigured: The included URLconf '<module 'book_app.urls' from 'C:\\Users\\Mr Dawani\\Desktop\\python_stack\\pythonstack\\django\\django_orm\\book_authors\\book_app\\urls.py'>' does not appear to have any patterns in it. If you see valid patterns in the file then the issue is probably caused by a circular import.

(djangoPy3Env) C:\Users\Mr Dawani\Desktop\python_stack\pythonstack\django\django_orm\book_authors>python manage.py makemigrations
Traceback (most recent call last):
  File "manage.py", line 21, in <module>
    main()
  File "manage.py", line 17, in main
    execute_from_command_line(sys.argv)
  File "C:\Users\Mr Dawani\Desktop\python_stack\pythonstack\django\djangoPy3Env\lib\site-packages\django\core\management\__init__.py", line 381, in execute_from_command_line
    utility.execute()
  File "C:\Users\Mr Dawani\Desktop\python_stack\pythonstack\django\djangoPy3Env\lib\site-packages\django\core\management\__init__.py", line 375, in execute
    self.fetch_command(subcommand).run_from_argv(self.argv)
  File "C:\Users\Mr Dawani\Desktop\python_stack\pythonstack\django\djangoPy3Env\lib\site-packages\django\core\management\base.py", line 323, in run_from_argv
    self.execute(*args, **cmd_options)
  File "C:\Users\Mr Dawani\Desktop\python_stack\pythonstack\django\djangoPy3Env\lib\site-packages\django\core\management\base.py", line 361, in execute
    self.check()
  File "C:\Users\Mr Dawani\Desktop\python_stack\pythonstack\django\djangoPy3Env\lib\site-packages\django\core\management\base.py", line 390, in check
    include_deployment_checks=include_deployment_checks,
  File "C:\Users\Mr Dawani\Desktop\python_stack\pythonstack\django\djangoPy3Env\lib\site-packages\django\core\management\base.py", line 377, in _run_checks
    return checks.run_checks(**kwargs)
  File "C:\Users\Mr Dawani\Desktop\python_stack\pythonstack\django\djangoPy3Env\lib\site-packages\django\core\checks\registry.py", line 72, in run_checks
    new_errors = check(app_configs=app_configs)
  File "C:\Users\Mr Dawani\Desktop\python_stack\pythonstack\django\djangoPy3Env\lib\site-packages\django\core\checks\urls.py", line 13, in check_url_config
    return check_resolver(resolver)
  File "C:\Users\Mr Dawani\Desktop\python_stack\pythonstack\django\djangoPy3Env\lib\site-packages\django\core\checks\urls.py", line 23, in check_resolver
    return check_method()
  File "C:\Users\Mr Dawani\Desktop\python_stack\pythonstack\django\djangoPy3Env\lib\site-packages\django\urls\resolvers.py", line 398, in check
    for pattern in self.url_patterns:
  File "C:\Users\Mr Dawani\Desktop\python_stack\pythonstack\django\djangoPy3Env\lib\site-packages\django\utils\functional.py", line 80, in __get__
    res = instance.__dict__[self.name] = self.func(instance)
  File "C:\Users\Mr Dawani\Desktop\python_stack\pythonstack\django\djangoPy3Env\lib\site-packages\django\urls\resolvers.py", line 579, in url_patterns
    patterns = getattr(self.urlconf_module, "urlpatterns", self.urlconf_module)
  File "C:\Users\Mr Dawani\Desktop\python_stack\pythonstack\django\djangoPy3Env\lib\site-packages\django\utils\functional.py", line 80, in __get__
    res = instance.__dict__[self.name] = self.func(instance)
  File "C:\Users\Mr Dawani\Desktop\python_stack\pythonstack\django\djangoPy3Env\lib\site-packages\django\urls\resolvers.py", line 572, in urlconf_module
    return import_module(self.urlconf_name)
  File "C:\Users\Mr Dawani\AppData\Local\Programs\Python\Python36-32\lib\importlib\__init__.py", line 126, in import_module
    return _bootstrap._gcd_import(name[level:], package, level)
  File "<frozen importlib._bootstrap>", line 994, in _gcd_import
  File "<frozen importlib._bootstrap>", line 971, in _find_and_load
  File "<frozen importlib._bootstrap>", line 955, in _find_and_load_unlocked
  File "<frozen importlib._bootstrap>", line 665, in _load_unlocked
  File "<frozen importlib._bootstrap_external>", line 678, in exec_module
  File "<frozen importlib._bootstrap>", line 219, in _call_with_frames_removed
  File "C:\Users\Mr Dawani\Desktop\python_stack\pythonstack\django\django_orm\book_authors\book_authors\urls.py", line 22, in <module>
    path('', include("book_app.urls"))
  File "C:\Users\Mr Dawani\Desktop\python_stack\pythonstack\django\djangoPy3Env\lib\site-packages\django\urls\conf.py", line 34, in include
    urlconf_module = import_module(urlconf_module)
  File "C:\Users\Mr Dawani\AppData\Local\Programs\Python\Python36-32\lib\importlib\__init__.py", line 126, in import_module
    return _bootstrap._gcd_import(name[level:], package, level)
  File "<frozen importlib._bootstrap>", line 994, in _gcd_import
  File "<frozen importlib._bootstrap>", line 971, in _find_and_load
  File "<frozen importlib._bootstrap>", line 955, in _find_and_load_unlocked
  File "<frozen importlib._bootstrap>", line 665, in _load_unlocked
  File "<frozen importlib._bootstrap_external>", line 678, in exec_module
  File "<frozen importlib._bootstrap>", line 219, in _call_with_frames_removed
  File "C:\Users\Mr Dawani\Desktop\python_stack\pythonstack\django\django_orm\book_authors\book_app\urls.py", line 8, in <module>
    path('',views.index)
AttributeError: module 'book_app.views' has no attribute 'index'

(djangoPy3Env) C:\Users\Mr Dawani\Desktop\python_stack\pythonstack\django\django_orm\book_authors>python manage.py migrate
Traceback (most recent call last):
  File "manage.py", line 21, in <module>
    main()
  File "manage.py", line 17, in main
    execute_from_command_line(sys.argv)
  File "C:\Users\Mr Dawani\Desktop\python_stack\pythonstack\django\djangoPy3Env\lib\site-packages\django\core\management\__init__.py", line 381, in execute_from_command_line
    utility.execute()
  File "C:\Users\Mr Dawani\Desktop\python_stack\pythonstack\django\djangoPy3Env\lib\site-packages\django\core\management\__init__.py", line 375, in execute
    self.fetch_command(subcommand).run_from_argv(self.argv)
  File "C:\Users\Mr Dawani\Desktop\python_stack\pythonstack\django\djangoPy3Env\lib\site-packages\django\core\management\base.py", line 323, in run_from_argv
    self.execute(*args, **cmd_options)
  File "C:\Users\Mr Dawani\Desktop\python_stack\pythonstack\django\djangoPy3Env\lib\site-packages\django\core\management\base.py", line 361, in execute
    self.check()
  File "C:\Users\Mr Dawani\Desktop\python_stack\pythonstack\django\djangoPy3Env\lib\site-packages\django\core\management\base.py", line 390, in check
    include_deployment_checks=include_deployment_checks,
  File "C:\Users\Mr Dawani\Desktop\python_stack\pythonstack\django\djangoPy3Env\lib\site-packages\django\core\management\commands\migrate.py", line 65, in _run_checks
    issues.extend(super()._run_checks(**kwargs))
  File "C:\Users\Mr Dawani\Desktop\python_stack\pythonstack\django\djangoPy3Env\lib\site-packages\django\core\management\base.py", line 377, in _run_checks
    return checks.run_checks(**kwargs)
  File "C:\Users\Mr Dawani\Desktop\python_stack\pythonstack\django\djangoPy3Env\lib\site-packages\django\core\checks\registry.py", line 72, in run_checks
    new_errors = check(app_configs=app_configs)
  File "C:\Users\Mr Dawani\Desktop\python_stack\pythonstack\django\djangoPy3Env\lib\site-packages\django\core\checks\urls.py", line 13, in check_url_config
    return check_resolver(resolver)
  File "C:\Users\Mr Dawani\Desktop\python_stack\pythonstack\django\djangoPy3Env\lib\site-packages\django\core\checks\urls.py", line 23, in check_resolver
    return check_method()
  File "C:\Users\Mr Dawani\Desktop\python_stack\pythonstack\django\djangoPy3Env\lib\site-packages\django\urls\resolvers.py", line 398, in check
    for pattern in self.url_patterns:
  File "C:\Users\Mr Dawani\Desktop\python_stack\pythonstack\django\djangoPy3Env\lib\site-packages\django\utils\functional.py", line 80, in __get__
    res = instance.__dict__[self.name] = self.func(instance)
  File "C:\Users\Mr Dawani\Desktop\python_stack\pythonstack\django\djangoPy3Env\lib\site-packages\django\urls\resolvers.py", line 579, in url_patterns
    patterns = getattr(self.urlconf_module, "urlpatterns", self.urlconf_module)
  File "C:\Users\Mr Dawani\Desktop\python_stack\pythonstack\django\djangoPy3Env\lib\site-packages\django\utils\functional.py", line 80, in __get__
    res = instance.__dict__[self.name] = self.func(instance)
  File "C:\Users\Mr Dawani\Desktop\python_stack\pythonstack\django\djangoPy3Env\lib\site-packages\django\urls\resolvers.py", line 572, in urlconf_module
    return import_module(self.urlconf_name)
  File "C:\Users\Mr Dawani\AppData\Local\Programs\Python\Python36-32\lib\importlib\__init__.py", line 126, in import_module
    return _bootstrap._gcd_import(name[level:], package, level)
  File "<frozen importlib._bootstrap>", line 994, in _gcd_import
  File "<frozen importlib._bootstrap>", line 971, in _find_and_load
  File "<frozen importlib._bootstrap>", line 955, in _find_and_load_unlocked
  File "<frozen importlib._bootstrap>", line 665, in _load_unlocked
  File "<frozen importlib._bootstrap_external>", line 678, in exec_module
  File "<frozen importlib._bootstrap>", line 219, in _call_with_frames_removed
  File "C:\Users\Mr Dawani\Desktop\python_stack\pythonstack\django\django_orm\book_authors\book_authors\urls.py", line 22, in <module>
    path('', include("book_app.urls"))
  File "C:\Users\Mr Dawani\Desktop\python_stack\pythonstack\django\djangoPy3Env\lib\site-packages\django\urls\conf.py", line 34, in include
    urlconf_module = import_module(urlconf_module)
  File "C:\Users\Mr Dawani\AppData\Local\Programs\Python\Python36-32\lib\importlib\__init__.py", line 126, in import_module
    return _bootstrap._gcd_import(name[level:], package, level)
  File "<frozen importlib._bootstrap>", line 994, in _gcd_import
  File "<frozen importlib._bootstrap>", line 971, in _find_and_load
  File "<frozen importlib._bootstrap>", line 955, in _find_and_load_unlocked
  File "<frozen importlib._bootstrap>", line 665, in _load_unlocked
  File "<frozen importlib._bootstrap_external>", line 678, in exec_module
  File "<frozen importlib._bootstrap>", line 219, in _call_with_frames_removed
  File "C:\Users\Mr Dawani\Desktop\python_stack\pythonstack\django\django_orm\book_authors\book_app\urls.py", line 8, in <module>
    path('',views.index)
AttributeError: module 'book_app.views' has no attribute 'index'

(djangoPy3Env) C:\Users\Mr Dawani\Desktop\python_stack\pythonstack\django\django_orm\book_authors>python manage.py makemigrations
No changes detected

(djangoPy3Env) C:\Users\Mr Dawani\Desktop\python_stack\pythonstack\django\django_orm\book_authors>python manage.py migrate
Operations to perform:
  Apply all migrations: admin, auth, contenttypes, sessions
Running migrations:
  No migrations to apply.

(djangoPy3Env) C:\Users\Mr Dawani\Desktop\python_stack\pythonstack\django\django_orm\book_authors>python manage.py shell
Python 3.6.4 (v3.6.4:d48eceb, Dec 19 2017, 06:04:45) [MSC v.1900 32 bit (Intel)] on win32
Type "help", "copyright", "credits" or "license" for more information.
(InteractiveConsole)
>>> exit()

(djangoPy3Env) C:\Users\Mr Dawani\Desktop\python_stack\pythonstack\django\django_orm\book_authors>python manage.py makemigrations
Migrations for 'book_app':
  book_app\migrations\0001_initial.py
    - Create model Book
    - Create model Publisher

(djangoPy3Env) C:\Users\Mr Dawani\Desktop\python_stack\pythonstack\django\django_orm\book_authors>python manage.py migrate
Operations to perform:
  Apply all migrations: admin, auth, book_app, contenttypes, sessions
Running migrations:
  Applying book_app.0001_initial... OK

(djangoPy3Env) C:\Users\Mr Dawani\Desktop\python_stack\pythonstack\django\django_orm\book_authors>python manage.py shell
Python 3.6.4 (v3.6.4:d48eceb, Dec 19 2017, 06:04:45) [MSC v.1900 32 bit (Intel)] on win32
Type "help", "copyright", "credits" or "license" for more information.
(InteractiveConsole)
>>> from books_app.models import *
Traceback (most recent call last):
  File "<console>", line 1, in <module>
ModuleNotFoundError: No module named 'books_app'
>>> from book_app.models import *
>>> book1=Book.objects.create(title="c sharp")
>>> book2=Book.objects.create(title="java")
>>> book3=Book.objects.create(title="python")
>>> book4=Book.objects.create(title="php")
>>> book5=Book.objects.create(title="ruby")
>>> publisher1=Publisher.objects.create(name="jane austin")
>>> publisher1=Publisher.objects.create(name="Emile Dickinson")
>>> publisher3=Publisher.objects.create(name="Fyodor Dostoevsky")
>>> publisher1=Publisher.objects.create(name="jane austin")
>>> publisher2=Publisher.objects.create(name="Emile Dickinson")
>>> publisher3=Publisher.objects.create(name="Fyodor Dostoevsky")
>>> publisher4=Publisher.objects.create(name="William Shakespeare")
>>> publisher5=Publisher.objects.create(name="Lau Tzu")
>>> exit()

(djangoPy3Env) C:\Users\Mr Dawani\Desktop\python_stack\pythonstack\django\django_orm\book_authors>python manage.py makemigrations
Traceback (most recent call last):
  File "manage.py", line 21, in <module>
    main()
  File "manage.py", line 17, in main
    execute_from_command_line(sys.argv)
  File "C:\Users\Mr Dawani\Desktop\python_stack\pythonstack\django\djangoPy3Env\lib\site-packages\django\core\management\__init__.py", line 381, in execute_from_command_line
    utility.execute()
  File "C:\Users\Mr Dawani\Desktop\python_stack\pythonstack\django\djangoPy3Env\lib\site-packages\django\core\management\__init__.py", line 357, in execute
    django.setup()
  File "C:\Users\Mr Dawani\Desktop\python_stack\pythonstack\django\djangoPy3Env\lib\site-packages\django\__init__.py", line 24, in setup
    apps.populate(settings.INSTALLED_APPS)
  File "C:\Users\Mr Dawani\Desktop\python_stack\pythonstack\django\djangoPy3Env\lib\site-packages\django\apps\registry.py", line 114, in populate
    app_config.import_models()
  File "C:\Users\Mr Dawani\Desktop\python_stack\pythonstack\django\djangoPy3Env\lib\site-packages\django\apps\config.py", line 211, in import_models
    self.models_module = import_module(models_module_name)
  File "C:\Users\Mr Dawani\AppData\Local\Programs\Python\Python36-32\lib\importlib\__init__.py", line 126, in import_module
    return _bootstrap._gcd_import(name[level:], package, level)
  File "<frozen importlib._bootstrap>", line 994, in _gcd_import
  File "<frozen importlib._bootstrap>", line 971, in _find_and_load
  File "<frozen importlib._bootstrap>", line 955, in _find_and_load_unlocked
  File "<frozen importlib._bootstrap>", line 665, in _load_unlocked
  File "<frozen importlib._bootstrap_external>", line 678, in exec_module
  File "<frozen importlib._bootstrap>", line 219, in _call_with_frames_removed
  File "C:\Users\Mr Dawani\Desktop\python_stack\pythonstack\django\django_orm\book_authors\book_app\models.py", line 7, in <module>
    class Publisher(models.Model):
  File "C:\Users\Mr Dawani\Desktop\python_stack\pythonstack\django\django_orm\book_authors\book_app\models.py", line 10, in Publisher
    notes = models.textField(null = True)
AttributeError: module 'django.db.models' has no attribute 'textField'

(djangoPy3Env) C:\Users\Mr Dawani\Desktop\python_stack\pythonstack\django\django_orm\book_authors>python manage.py makemigrations
Migrations for 'book_app':
  book_app\migrations\0002_publisher_notes.py
    - Add field notes to publisher

(djangoPy3Env) C:\Users\Mr Dawani\Desktop\python_stack\pythonstack\django\django_orm\book_authors>python manage.py migrate
Operations to perform:
  Apply all migrations: admin, auth, book_app, contenttypes, sessions
Running migrations:
  Applying book_app.0002_publisher_notes... OK

(djangoPy3Env) C:\Users\Mr Dawani\Desktop\python_stack\pythonstack\django\django_orm\book_authors>python manage.py shell
Python 3.6.4 (v3.6.4:d48eceb, Dec 19 2017, 06:04:45) [MSC v.1900 32 bit (Intel)] on win32
Type "help", "copyright", "credits" or "license" for more information.
(InteractiveConsole)
>>> import book_app.models import *
  File "<console>", line 1
    import book_app.models import *
                                ^
SyntaxError: invalid syntax
>>> from book_app.models import *
>>> print (book1)
Traceback (most recent call last):
  File "<console>", line 1, in <module>
NameError: name 'book1' is not defined
>>> print (Book1)
Traceback (most recent call last):
  File "<console>", line 1, in <module>
NameError: name 'Book1' is not defined
>>> print(book.objects.all().value())
Traceback (most recent call last):
  File "<console>", line 1, in <module>
NameError: name 'book' is not defined
>>> print(Book.objects.all().value())
Traceback (most recent call last):
  File "<console>", line 1, in <module>
AttributeError: 'QuerySet' object has no attribute 'value'
>>> print(Book.objects.all())
<QuerySet [<Book: Book object (1)>, <Book: Book object (2)>, <Book: Book object (3)>, <Book: Book object (4)>, <Book: Book object (5)>]>
>>> Book.object.get(id=1).title = c#
Traceback (most recent call last):
  File "<console>", line 1, in <module>
NameError: name 'c' is not defined
>>> Book.object.get(id=1).title = "c#"
Traceback (most recent call last):
  File "<console>", line 1, in <module>
AttributeError: type object 'Book' has no attribute 'object'
>>> Book.objects.get(id=1).title = "c#"
>>> Publisher.objects.get(id=4).name = "bill"
>>> print(Publisher.objects.get(id=4))
Publisher object (4)
>>> print Publisher.objects.(id=4)
  File "<console>", line 1
    print Publisher.objects.(id=4)
                  ^
SyntaxError: invalid syntax
>>> print( Publisher.objects.(id=4))
  File "<console>", line 1
    print( Publisher.objects.(id=4))
                             ^
SyntaxError: invalid syntax
>>> Publisher.objects.(id=4).name
  File "<console>", line 1
    Publisher.objects.(id=4).name
                      ^
SyntaxError: invalid syntax
>>> Publisher.objects.all().values()
<QuerySet [{'id': 1, 'name': 'jane austin', 'notes': None, 'created_at': datetime.datetime(2021, 5, 23, 19, 28, 28, 22496, tzinfo=<UTC>), 'updated_at': datetime.datetime(2021, 5, 23, 19, 28, 28, 22496, tzinfo=<UTC>)}, {'id': 2, 'name': 'Emile Dickinson', 'notes': None, 'created_at': datetime.datetime(2021, 5, 23, 19, 30, 9, 942253, tzinfo=<UTC>), 'updated_at': datetime.datetime(2021, 5, 23, 19, 30, 9, 943270, tzinfo=<UTC>)}, {'id': 3, 'name': 'Fyodor Dostoevsky', 'notes': None, 'created_at': datetime.datetime(2021, 5, 23, 19, 30, 41, 629103, tzinfo=<UTC>), 'updated_at': datetime.datetime(2021, 5, 23, 19, 30, 41, 629103, tzinfo=<UTC>)}, {'id': 4, 'name': 'jane austin', 'notes': None, 'created_at': datetime.datetime(2021, 5, 23, 19, 30, 59, 127066, tzinfo=<UTC>), 'updated_at': datetime.datetime(2021, 5, 23, 19, 30, 59, 127066, tzinfo=<UTC>)}, {'id': 5, 'name': 'Emile Dickinson', 'notes': None, 'created_at': datetime.datetime(2021, 5, 23, 19, 31, 17, 915695, tzinfo=<UTC>), 'updated_at': datetime.datetime(2021, 5, 23, 19, 31, 17, 915695, tzinfo=<UTC>)}, {'id': 6, 'name': 'Fyodor Dostoevsky', 'notes': None, 'created_at': datetime.datetime(2021, 5, 23, 19, 31, 23, 23763, tzinfo=<UTC>), 'updated_at': datetime.datetime(2021, 5, 23, 19, 31, 23, 23763, tzinfo=<UTC>)}, {'id': 7, 'name': 'William Shakespeare', 'notes': None, 'created_at': datetime.datetime(2021, 5, 23, 19, 31, 58, 45530, tzinfo=<UTC>), 'updated_at': datetime.datetime(2021, 5, 23, 19, 31, 58, 45530, tzinfo=<UTC>)}, {'id': 8, 'name': 'Lau Tzu', 'notes': None, 'created_at': datetime.datetime(2021, 5, 23, 19, 32, 19, 212445, tzinfo=<UTC>), 'updated_at': datetime.datetime(2021, 5, 23, 19, 32, 19, 213466, tzinfo=<UTC>)}]>
>>> Publisher.all().delete
Traceback (most recent call last):
  File "<console>", line 1, in <module>
AttributeError: type object 'Publisher' has no attribute 'all'
>>> Publisher.objects.all().delete()
(8, {'book_app.Publisher_books': 0, 'book_app.Publisher': 8})
>>> publisher1=Publisher.objects.create(name="jane austin")
>>> publisher2=Publisher.objects.create(name="Emile Dickinson")
>>> publisher3=Publisher.objects.create(name="Fyodor Dostoevsky")
>>> publisher4=Publisher.objects.create(name="William Shakespeare")
>>> publisher5=Publisher.objects.create(name="Lau Tzu")
>>> Publisher.objects.all().values()
<QuerySet [{'id': 9, 'name': 'jane austin', 'notes': None, 'created_at': datetime.datetime(2021, 5, 23, 19, 47, 34, 533791, tzinfo=<UTC>), 'updated_at': datetime.datetime(2021, 5, 23, 19, 47, 34, 533791, tzinfo=<UTC>)}, {'id': 10, 'name': 'Emile Dickinson', 'notes': None, 'created_at': datetime.datetime(2021, 5, 23, 19, 47, 40, 122359, tzinfo=<UTC>), 'updated_at': datetime.datetime(2021, 5, 23, 19, 47, 40, 122359, tzinfo=<UTC>)}, {'id': 11, 'name': 'Fyodor Dostoevsky', 'notes': None, 'created_at': datetime.datetime(2021, 5, 23, 19, 47, 44, 157352, tzinfo=<UTC>), 'updated_at': datetime.datetime(2021, 5, 23, 19, 47, 44, 157352, tzinfo=<UTC>)}, {'id': 12, 'name': 'William Shakespeare', 'notes': None, 'created_at': datetime.datetime(2021, 5, 23, 19, 47, 46, 206543, tzinfo=<UTC>), 'updated_at': datetime.datetime(2021, 5, 23, 19, 47, 46, 206543, tzinfo=<UTC>)}, {'id': 13, 'name': 'Lau Tzu', 'notes': None, 'created_at': datetime.datetime(2021, 5, 23, 19, 47, 48, 89572, tzinfo=<UTC>), 'updated_at': datetime.datetime(2021, 5, 23, 19, 47, 48, 89572, tzinfo=<UTC>)}]>
>>> hello=Publisher.objects.get(id=12)
>>> hello.name = "Bill"
>>> Publisher.objects.all().values()
<QuerySet [{'id': 9, 'name': 'jane austin', 'notes': None, 'created_at': datetime.datetime(2021, 5, 23, 19, 47, 34, 533791, tzinfo=<UTC>), 'updated_at': datetime.datetime(2021, 5, 23, 19, 47, 34, 533791, tzinfo=<UTC>)}, {'id': 10, 'name': 'Emile Dickinson', 'notes': None, 'created_at': datetime.datetime(2021, 5, 23, 19, 47, 40, 122359, tzinfo=<UTC>), 'updated_at': datetime.datetime(2021, 5, 23, 19, 47, 40, 122359, tzinfo=<UTC>)}, {'id': 11, 'name': 'Fyodor Dostoevsky', 'notes': None, 'created_at': datetime.datetime(2021, 5, 23, 19, 47, 44, 157352, tzinfo=<UTC>), 'updated_at': datetime.datetime(2021, 5, 23, 19, 47, 44, 157352, tzinfo=<UTC>)}, {'id': 12, 'name': 'William Shakespeare', 'notes': None, 'created_at': datetime.datetime(2021, 5, 23, 19, 47, 46, 206543, tzinfo=<UTC>), 'updated_at': datetime.datetime(2021, 5, 23, 19, 47, 46, 206543, tzinfo=<UTC>)}, {'id': 13, 'name': 'Lau Tzu', 'notes': None, 'created_at': datetime.datetime(2021, 5, 23, 19, 47, 48, 89572, tzinfo=<UTC>), 'updated_at': datetime.datetime(2021, 5, 23, 19, 47, 48, 89572, tzinfo=<UTC>)}]>
>>> Publisher.objects.get(id=12).update (name = "bill")
Traceback (most recent call last):
  File "<console>", line 1, in <module>
AttributeError: 'Publisher' object has no attribute 'update'
>>> Publisher.objects.filter(id=12).update(name = "bill")
1
>>> Publisher.objects.all().values()
<QuerySet [{'id': 9, 'name': 'jane austin', 'notes': None, 'created_at': datetime.datetime(2021, 5, 23, 19, 47, 34, 533791, tzinfo=<UTC>), 'updated_at': datetime.datetime(2021, 5, 23, 19, 47, 34, 533791, tzinfo=<UTC>)}, {'id': 10, 'name': 'Emile Dickinson', 'notes': None, 'created_at': datetime.datetime(2021, 5, 23, 19, 47, 40, 122359, tzinfo=<UTC>), 'updated_at': datetime.datetime(2021, 5, 23, 19, 47, 40, 122359, tzinfo=<UTC>)}, {'id': 11, 'name': 'Fyodor Dostoevsky', 'notes': None, 'created_at': datetime.datetime(2021, 5, 23, 19, 47, 44, 157352, tzinfo=<UTC>), 'updated_at': datetime.datetime(2021, 5, 23, 19, 47, 44, 157352, tzinfo=<UTC>)}, {'id': 12, 'name': 'bill', 'notes': None, 'created_at': datetime.datetime(2021, 5, 23, 19, 47, 46, 206543, tzinfo=<UTC>), 'updated_at': datetime.datetime(2021, 5, 23, 19, 47, 46, 206543, tzinfo=<UTC>)}, {'id': 13, 'name': 'Lau Tzu', 'notes': None, 'created_at': datetime.datetime(2021, 5, 23, 19, 47, 48, 89572, tzinfo=<UTC>), 'updated_at': datetime.datetime(2021, 5, 23, 19, 47, 48, 89572, tzinfo=<UTC>)}]>
>>> publisher1.books.add(book1,book2)
Traceback (most recent call last):
  File "<console>", line 1, in <module>
NameError: name 'book1' is not defined
>>> publisher1.books.add(book1)
Traceback (most recent call last):
  File "<console>", line 1, in <module>
NameError: name 'book1' is not defined
>>> book1
Traceback (most recent call last):
  File "<console>", line 1, in <module>
NameError: name 'book1' is not defined
>>> publisher1.books.add(Book.objects.get(id=1))
>>> publisher1
<Publisher: Publisher object (9)>
>>> publisher1.value()
Traceback (most recent call last):
  File "<console>", line 1, in <module>
AttributeError: 'Publisher' object has no attribute 'value'
>>> publisher1.values()
Traceback (most recent call last):
  File "<console>", line 1, in <module>
AttributeError: 'Publisher' object has no attribute 'values'
>>> Publisher.objects.all().values()
<QuerySet [{'id': 9, 'name': 'jane austin', 'notes': None, 'created_at': datetime.datetime(2021, 5, 23, 19, 47, 34, 533791, tzinfo=<UTC>), 'updated_at': datetime.datetime(2021, 5, 23, 19, 47, 34, 533791, tzinfo=<UTC>)}, {'id': 10, 'name': 'Emile Dickinson', 'notes': None, 'created_at': datetime.datetime(2021, 5, 23, 19, 47, 40, 122359, tzinfo=<UTC>), 'updated_at': datetime.datetime(2021, 5, 23, 19, 47, 40, 122359, tzinfo=<UTC>)}, {'id': 11, 'name': 'Fyodor Dostoevsky', 'notes': None, 'created_at': datetime.datetime(2021, 5, 23, 19, 47, 44, 157352, tzinfo=<UTC>), 'updated_at': datetime.datetime(2021, 5, 23, 19, 47, 44, 157352, tzinfo=<UTC>)}, {'id': 12, 'name': 'bill', 'notes': None, 'created_at': datetime.datetime(2021, 5, 23, 19, 47, 46, 206543, tzinfo=<UTC>), 'updated_at': datetime.datetime(2021, 5, 23, 19, 47, 46, 206543, tzinfo=<UTC>)}, {'id': 13, 'name': 'Lau Tzu', 'notes': None, 'created_at': datetime.datetime(2021, 5, 23, 19, 47, 48, 89572, tzinfo=<UTC>), 'updated_at': datetime.datetime(2021, 5, 23, 19, 47, 48, 89572, tzinfo=<UTC>)}]>
>>> publisher1.books.add(Book.objects.get(id=1))
>>> print(publisher1)
Publisher object (9)
>>> publisher.objects.get(id=1)
Traceback (most recent call last):
  File "<console>", line 1, in <module>
NameError: name 'publisher' is not defined
>>> Publisher.objects.get(id=1)
Traceback (most recent call last):
  File "<console>", line 1, in <module>
  File "C:\Users\Mr Dawani\Desktop\python_stack\pythonstack\django\djangoPy3Env\lib\site-packages\django\db\models\manager.py", line 82, in manager_method
    return getattr(self.get_queryset(), name)(*args, **kwargs)
  File "C:\Users\Mr Dawani\Desktop\python_stack\pythonstack\django\djangoPy3Env\lib\site-packages\django\db\models\query.py", line 408, in get
    self.model._meta.object_name
book_app.models.Publisher.DoesNotExist: Publisher matching query does not exist.
>>> publisher1.books.all()
<QuerySet [<Book: Book object (1)>]>
>>> publisher1.books.all().values()
<QuerySet [{'id': 1, 'title': 'c sharp', 'created_at': datetime.datetime(2021, 5, 23, 19, 24, 34, 346484, tzinfo=<UTC>), 'updated_at': datetime.datetime(2021, 5, 23, 19, 24, 34, 346484, tzinfo=<UTC>)}]>
>>>
>>> publisher2.books.all().values()
<QuerySet []>
>>> publisher1.books.add(Book.objects.get(id=2))
>>> publisher2
<Publisher: Publisher object (10)>
>>> publisher2.Books.add(Book.objects.get(id=1))
Traceback (most recent call last):
  File "<console>", line 1, in <module>
AttributeError: 'Publisher' object has no attribute 'Books'
>>> publisher2.Book.add(Book.objects.get(id=1))
Traceback (most recent call last):
  File "<console>", line 1, in <module>
AttributeError: 'Publisher' object has no attribute 'Book'
>>> publisher2.books.add(Book.objects.get(id=1))
>>> publisher2.books.add(Book.objects.get(id=2))
>>> publisher2.books.add(Book.objects.get(id=3))
>>> publisher2.books.add(Book.objects.get(id=4))
>>> publisher3
<Publisher: Publisher object (11)>
>>> publisher3.books.add(Book.objects.get(id=1))
>>> publisher3.books.add(Book.objects.get(id=2))
>>> publisher3.books.add(Book.objects.get(id=3))
>>> publisher4.books.add.all()
Traceback (most recent call last):
  File "<console>", line 1, in <module>
AttributeError: 'function' object has no attribute 'all'
>>> publisher4.books.add(Book.abjects.all())
Traceback (most recent call last):
  File "<console>", line 1, in <module>
AttributeError: type object 'Book' has no attribute 'abjects'
>>> publisher4.books.add(Book.objects.get(id=1))
>>> publisher4.books.add(Book.objects.get(id=2))
>>> publisher4.books.add(Book.objects.get(id=3))
>>> publisher4.books.add(Book.objects.get(id=4))
>>> publisher4.books.add(Book.objects.get(id=5))
>>> book3
Traceback (most recent call last):
  File "<console>", line 1, in <module>
NameError: name 'book3' is not defined
>>> book3=Book.objects.get(id=3)
>>> book3.publishers.all()
<QuerySet [<Publisher: Publisher object (10)>, <Publisher: Publisher object (11)>, <Publisher: Publisher object (12)>]>
>>> book3.publishers.remove(publisher1)
>>> book3.publishers.all()
<QuerySet [<Publisher: Publisher object (10)>, <Publisher: Publisher object (11)>, <Publisher: Publisher object (12)>]>
>>> publisher1
<Publisher: Publisher object (9)>
>>> book3.publishers.remove(publisher2)
>>> book3.publishers.all()
<QuerySet [<Publisher: Publisher object (11)>, <Publisher: Publisher object (12)>]>
>>> book2
Traceback (most recent call last):
  File "<console>", line 1, in <module>
NameError: name 'book2' is not defined
>>> book2=Book.objects.get(id=2)
>>> book2.publishers.all()
<QuerySet [<Publisher: Publisher object (9)>, <Publisher: Publisher object (10)>, <Publisher: Publisher object (11)>, <Publisher: Publisher object (12)>]>
>>> book2.publishers.add(publisher5)
>>> book2.publishers.all()
<QuerySet [<Publisher: Publisher object (9)>, <Publisher: Publisher object (10)>, <Publisher: Publisher object (11)>, <Publisher: Publisher object (12)>, <Publisher: Publisher object (13)>]>
>>> publisher3.books.all()
<QuerySet [<Book: Book object (1)>, <Book: Book object (2)>, <Book: Book object (3)>]>
>>> book5.publishers.all()
Traceback (most recent call last):
  File "<console>", line 1, in <module>
NameError: name 'book5' is not defined
>>> book5=Book.objects.get(id=5)
>>> book5.publishers.all()
<QuerySet [<Publisher: Publisher object (12)>]>
>>>